<mujoco model="HPC_custom">
  <compiler angle="radian" coordinate="local" inertiafromgeom="false" />
  <default>
    <joint damping="0.0" />
    <geom contype="0" friction="0.0 0.0 0.0" />
  </default>
  <option gravity="0 0 -9.81" integrator="RK4" timestep="0.025" />
  <size nstack="3000" nuser_actuator="10" nuserdata="100" />
  <worldbody>
    <geom name="floor" pos="0 0 -3" rgba="1 1 1 1" size="40 40 40" type="plane" />
    <body name="leg" pos="0 0 0">
      <joint axis="0 1 0" limited="true" name="hinge" pos="0 0 0" range="-0.1 0.22" type="hinge" />
      <geom fromto="0 0 0 0 0 0.7970" name="cpole" rgba="0.9 0.4 0.0 0.7" size="0.045" type="capsule" />
      <inertial diaginertia="0.878121 0.878121 0.001" mass="17.2955" pos="0 0 0.5084" />
      <body name="body" pos="0 0 0.7970">
        <joint axis="0 1 0" limited="true" name="hinge2" pos="0 0 0" range="-0.3 0.4" type="hinge" />
        <geom fromto="0 0 0 0 0 0.7520" name="cpole2" rgba="0.8 0.4 0.0 0.7" size="0.045" type="capsule" />
        <inertial diaginertia="1.047289 1.047289 0.001" mass="34.5085" pos="0 0 0.2814" />
      </body>
    </body>
  </worldbody>
  <actuator>
    <motor ctrllimited="true" ctrlrange="-1.0 1.0" gear="100" joint="hinge" />
    <motor ctrllimited="true" ctrlrange="-1.0 1.0" gear="100" joint="hinge2" />
  </actuator>
</mujoco>