<mujoco model="HPC_custom">
  <compiler angle="radian" coordinate="local" inertiafromgeom="false" />
  <default>
    <joint damping="0.0" />
    <geom contype="0" friction="0.0 0.0 0.0" />
  </default>
  <option gravity="0 0 -9.81" integrator="RK4" timestep="0.0016666666666667" />
  <size nstack="3000" nuser_actuator="10" nuserdata="100" />
  <worldbody>
    <geom name="floor" pos="0 0 -3" rgba="1 1 1 1" size="40 40 40" type="plane" />
    <body name="leg" pos="0 0 0">
      <joint axis="0 1 0" limited="true" name="hinge" pos="0 0 0" range="-0.5 0.5" type="hinge" />
      <geom fromto="0 0 0 0 0 0.8050" name="cpole" rgba="0.9 0.4 0.0 0.7" size="0.045" type="capsule" />
      <inertial diaginertia="1.073581 1.073581 0.001" mass="21.0865" pos="0 0 0.5160" />
      <body name="body" pos="0 0 0.8049999999999999">
        <joint axis="0 1 0" limited="true" name="hinge2" pos="0 0 0" range="-0.5 0.5" type="hinge" />
        <geom fromto="0 0 0 0 0 0.7980" name="cpole2" rgba="0.8 0.4 0.0 0.7" size="0.045" type="capsule" />
        <inertial diaginertia="1.432992 1.432992 0.001" mass="43.4886" pos="0 0 0.2941" />
      </body>
    </body>
  </worldbody>
  <actuator>
    <motor ctrllimited="true" ctrlrange="-1 1" gear="300" joint="hinge" />
    <motor ctrllimited="true" ctrlrange="-1 1" gear="300" joint="hinge2" />
  </actuator>
</mujoco>