<mujoco model="IDP_custom">
  <compiler angle="radian" coordinate="local" inertiafromgeom="false" />
  <default>
    <joint damping="0.0" />
    <geom contype="0" friction="0.0 0.0 0.0" />
  </default>
  <option gravity="0 0 -9.81" integrator="RK4" timestep="0.0083333333" />
  <size nstack="3000" nuser_actuator="10" nuserdata="100" />
  <worldbody>
    <geom name="floor" pos="0 0 -3" rgba="1 1 1 1" size="40 40 40" type="plane" />
    <body name="leg" pos="0 0 0">
      <joint axis="0 -1 0" limited="true" name="hinge" pos="0 0 0" range="-1.0 1.0" type="hinge" />
      <geom fromto="0 0 0 0 0 0.7750" name="cpole" rgba="0.9 0.4 0.0 0.7" size="0.045" type="capsule" />
      <inertial diaginertia="1.085280 1.085280 0.001" mass="23.7953" pos="0 0 0.5184" />
      <body name="body" pos="0 0 0.7750">
        <joint axis="0 -1 0" limited="true" name="hinge2" pos="0 0 0" range="-1.0 1.0" type="hinge" />
        <geom fromto="0 0 0 0 0 0.8400" name="cpole2" rgba="0.8 0.4 0.0 0.7" size="0.045" type="capsule" />
        <inertial diaginertia="2.227466 2.227466 0.001" mass="53.9829" pos="0 0 0.3189" />
      </body>
    </body>
  </worldbody>
  <actuator>
    <motor ctrllimited="true" ctrlrange="-1 1" gear="100" joint="hinge" />
    <motor ctrllimited="true" ctrlrange="-1 1" gear="100" joint="hinge2" />
  </actuator>
</mujoco>