<mujoco model="IDP_custom">
  <compiler angle="radian" coordinate="local" inertiafromgeom="false" />
  <default>
    <joint damping="0.0" />
    <geom contype="0" friction="0.0 0.0 0.0" />
  </default>
  <option gravity="0 0 -9.81" integrator="RK4" timestep="0.0083333333" />
  <size nstack="3000" nuser_actuator="10" nuserdata="100" />
  <asset>
    <texture builtin="gradient" height="100" rgb1=".4 .5 .6" rgb2="0 0 0" type="skybox" width="100" />
    <texture builtin="flat" height="1278" mark="cross" markrgb="1 1 1" name="texgeom" random="0.01" rgb1="0.8 0.6 0.4" rgb2="0.8 0.6 0.4" type="cube" width="127" />
    <texture builtin="checker" height="100" name="texplane" rgb1="0 0 0" rgb2="0.8 0.8 0.8" type="2d" width="100" />
    <material name="MatPlane" reflectance="0.5" shininess="1" specular="1" texrepeat="60 60" texture="texplane" />
    <material name="geom" texture="texgeom" texuniform="true" />
  </asset>
  <worldbody>
    <light cutoff="100" diffuse="1 1 1" dir="-0 0 -1.3" directional="true" exponent="1" pos="0 0 1.3" specular=".1 .1 .1" />
    <geom condim="3" friction="1 .1 .1" material="MatPlane" name="floor" pos="0 0 -0.1" rgba="0.8 0.9 0.8 1" size="20 20 0.125" type="plane" />
    <body name="leg" pos="0 0 0">
      <joint axis="0 -1 0" limited="true" name="hinge" pos="0 0 0" range="-1.0 1.0" type="hinge" />
      <geom fromto="0 0 0 0 0 0.7750" name="cpole" rgba="0.8 0.6 0.4 1.0" size="0.045" type="capsule" />
      <inertial diaginertia="1.085280 1.085280 0.001" mass="23.7953" pos="0 0 0.5184" />
      <body name="body" pos="0 0 0.7750">
        <joint axis="0 -1 0" limited="true" name="hinge2" pos="0 0 0" range="-1.0 1.0" type="hinge" />
        <geom fromto="0 0 0 0 0 0.8400" name="cpole2" rgba="0.8 0.6 0.4 1.0" size="0.045" type="capsule" />
        <inertial diaginertia="2.227466 2.227466 0.001" mass="53.9829" pos="0 0 0.3189" />
      </body>
    </body>
  </worldbody>
  <actuator>
    <motor ctrllimited="true" ctrlrange="-1 1" gear="100" joint="hinge" />
    <motor ctrllimited="true" ctrlrange="-1 1" gear="100" joint="hinge2" />
  </actuator>
</mujoco>