<mujoco model="IP-custom">
	<compiler angle="radian" coordinate="local" inertiafromgeom="false"/>
	<default>
		<joint damping="0.0"/>
		<geom contype="0" friction="0.0 0.0 0.0" rgba="0.7 0.7 0 1"/>
	</default>
	<option gravity="0 0 -9.81" integrator="RK4" timestep="0.025"/>
	<size nstack="3000" nuserdata="100" nuser_actuator="10"/>
	<worldbody>
		<body name="pole" pos="0 0 0">
			<joint axis="0 1 0" limited="true" range="-0.5 0.5" name="hinge" pos="0 0 0" type="hinge"/>
			<geom fromto="0 0 0 0 0 0.797" name="cpole" rgba="0 0.7 0.7 1" size="0.045" type="capsule"/>
			<inertial pos="0 0 0.5084" mass="17.2955" diaginertia="0.878121 0.878121 0.001"/>
		</body>
	</worldbody>
	<actuator>
		<motor ctrllimited="true" ctrlrange='-0.75 1.0' gear="40" joint="hinge"/>
	</actuator>
</mujoco>