<mujoco model="IP_custom">
	<compiler angle="radian" coordinate="local" inertiafromgeom="false" />
	<default>
		<joint damping="0.0" />
		<geom contype="0" friction="0.0 0.0 0.0" rgba="0.7 0.7 0 1" />
	</default>
	<option gravity="0 0 -9.81" integrator="RK4" timestep="0.008333333" />
	<size nstack="3000" nuser_actuator="10" nuserdata="100" />
  	<asset>
		<texture builtin="gradient" height="100" rgb1=".4 .5 .6" rgb2="0 0 0" type="skybox" width="100" />
		<texture builtin="flat" height="1278" mark="cross" markrgb="1 1 1" name="texgeom" random="0.01" rgb1="0.8 0.6 0.4" rgb2="0.8 0.6 0.4" type="cube" width="127" />
		<texture builtin="checker" height="100" name="texplane" rgb1="0 0 0" rgb2="0.8 0.8 0.8" type="2d" width="100" />
		<material name="MatPlane" reflectance="0.5" shininess="1" specular="1" texrepeat="60 60" texture="texplane" />
		<material name="geom" texture="texgeom" texuniform="true" />
	</asset>
	<worldbody>
		<light cutoff="100" diffuse="1 1 1" dir="-0 0 -1.3" directional="true" exponent="1" pos="0 0 1.3" specular=".1 .1 .1" />
    	<geom condim="3" friction="1 .1 .1" material="MatPlane" name="floor" pos="0 0 -0.1" rgba="0.8 0.9 0.8 1" size="20 20 0.125" type="plane" />
		<body name="pole" pos="0 0 0">
			<joint axis="0 -1 0" limited="true" name="hinge" pos="0 0 0" range="-0.5 0.5" type="hinge" />
			<geom fromto="0 0 0 0 0 1.6150" name="cpole" rgba="0.8 0.6 0.4 1.0" size="0.045" type="capsule" />
			<inertial diaginertia="8.781883 8.781883 0.001" mass="77.7782" pos="0 0 0.9178" />
		</body>
	</worldbody>
	<actuator>
		<motor ctrllimited="true" ctrlrange="-1.0 1.0" gear="100" joint="hinge" />
	</actuator>
</mujoco>