<mujoco model="IDP_custom">
  <compiler angle="radian" coordinate="local" inertiafromgeom="false" />
  <default>
    <joint damping="0.0" />
    <geom contype="0" friction="0.0 0.0 0.0" />
  </default>
  <option gravity="0 0 -9.81" integrator="RK4" timestep="0.0083333333" />
  <size nstack="3000" nuser_actuator="10" nuserdata="100" />
  <asset>
    <texture type="skybox" builtin="gradient" rgb1=".3 .5 .7" rgb2="0 0 0" width="32" height="512"/>
    <texture name="grid" type="2d" builtin="checker" width="512" height="512" rgb1=".1 .2 .3" rgb2=".2 .3 .4"/>
    <material name="grid" texture="grid" texrepeat="1 1" texuniform="true" reflectance=".2"/>
  </asset>
  <worldbody>
    <light cutoff="100" diffuse="1 1 1" dir="-0 0 -1.3" directional="true" exponent="1" pos="0 0 1.3" specular=".1 .1 .1" />
    <geom name="floor" size="0 0 .09" type="plane" material="grid" contype="0" conaffinity="0" condim="3" friction="2.0 0 0"/>
    <body name="foot" euler="0 0 0" pos="0 0 0">
      <geom fromto="-0.04 0 0 0.164 0 0" name="foot" rgba="0.8 0.6 0.4 1.0" size="0.04" type="capsule" contype="1" conaffinity="1"/>
<!--      <geom fromto="-0.04 0 0 0.164 0 0" name="foot" rgba="0.8 0.6 0.4 1.0" size="0.04" type="capsule"/>-->
      <inertial diaginertia="0.0064 0.0064 0.0001" mass="1.6764" pos="0 0 0" />
      <freejoint name="root"/>
      <body name="leg" pos="0 0 0.516" euler="0 0 0">
        <joint axis="0 1 0" damping="0.0" limited="true" name="ank" pos="0 0 -0.516" range="-1.5 1.5" stiffness="0.0" type="hinge" />
<!--        <joint axis="0 1 0" damping="0.0" limited="true" name="ank" pos="0 0 0" range="-1.0 1.0" stiffness="0.0" type="hinge" />-->
        <geom fromto="0 0 -0.516 0 0 0.2890" name="leg" rgba="0.8 0.6 0.4 1.0" size="0.045" contype="0" type="capsule" />
        <inertial diaginertia="1.073581 1.073581 0.0001" mass="21.0865" pos="0 0 0" />
        <body name="body" pos="0 0 0.5831">
          <joint axis="0 1 0" damping="0.0" limited="true" name="hip" pos="0 0 -0.2941" range="-2.5 2.5" stiffness="0.0" type="hinge" />
          <geom fromto="0 0 -0.2941 0 0 0.5039" name="upper_body" rgba="0.8 0.6 0.4 1.0" size="0.045" contype="0" type="capsule" />
          <inertial diaginertia="1.432992 1.432992 0.0001" mass="43.4886" pos="0 0 0" />
        </body>
      </body>
    </body>
  </worldbody>
  <actuator>
    <motor ctrllimited="true" ctrlrange="-1.0 1.0" gear="150" joint="ank" name="ank"/>
    <motor ctrllimited="true" ctrlrange="-1.0 1.0" gear="150" joint="hip" name="hip"/>
  </actuator>
</mujoco>
