<mujoco model="IDP_custom">
  <compiler angle="radian" coordinate="local" inertiafromgeom="false" />
  <default>
    <joint damping="0.0" />
    <geom contype="0" friction="0.0 0.0 0.0" />
  </default>
  <option gravity="0 0 -9.81" integrator="RK4" timestep="0.0083333333" />
  <size nstack="3000" nuser_actuator="10" nuserdata="100" />
  <asset>
    <texture builtin="gradient" height="100" rgb1=".4 .5 .6" rgb2="0 0 0" type="skybox" width="100" />
    <texture builtin="flat" height="1278" mark="cross" markrgb="1 1 1" name="texgeom" random="0.01" rgb1="0.8 0.6 0.4" rgb2="0.8 0.6 0.4" type="cube" width="127" />
    <texture builtin="checker" height="100" name="texplane" rgb1="0 0 0" rgb2="0.8 0.8 0.8" type="2d" width="100" />
    <material name="MatPlane" reflectance="0.5" shininess="1" specular="1" texrepeat="60 60" texture="texplane" />
    <material name="geom" texture="texgeom" texuniform="true" />
  </asset>
  <worldbody>
    <light cutoff="100" diffuse="1 1 1" dir="-0 0 -1.3" directional="true" exponent="1" pos="0 0 1.3" specular=".1 .1 .1" />
    <geom condim="3" friction="1 .1 .1" material="MatPlane" name="floor" pos="0 0 -0.03" rgba="0.8 0.9 0.8 1" size="20 20 0.125" type="plane" />
    <body name="foot" pos="0 0 0">
      <geom fromto="-0.1 0 0.04 0.15 0 0.04" name="foot" rgba="0.8 0.6 0.4 1.0" size="0.04" type="capsule" />
      <body name="shank" pos="0 0 0.13">
        <joint axis="0 -1 0" damping="0.0" limited="true" name="ank" pos="0 0 0" range="-1.0 1.0" stiffness="0.0" type="hinge" />
        <geom fromto="0 0 0 0 0 0.3050" name="shank" rgba="0.8 0.6 0.4 1.0" size="0.05" type="capsule" />
        <inertial diaginertia="1.073581 1.073581 0.001" mass="21.0865" pos="0 0 0.5160" />
        <body name="thigh" pos="0 0 0.411">
          <geom fromto="0 0 0 0 0 0.28" name="thigh" rgba="0.8 0.6 0.4 1.0" size="0.06" type="capsule" />
          <inertial diaginertia="1.073581 1.073581 0.001" mass="21.0865" pos="0 0 0.5160" />
          <body name="body" pos="0 0 0.44">
            <joint axis="0 -1 0" damping="0.0" limited="true" name="hip" pos="0 0 0" range="-2.1 2.1" stiffness="0.0" type="hinge" />
            <geom fromto="0 0 0 0 0 0.630" name="ubody" rgba="0.8 0.6 0.4 1.0" size="0.08" type="capsule" />
            <inertial diaginertia="1.432992 1.432992 0.001" mass="43.4886" pos="0 0 0.2941" />
            <body name="head" pos="0 0 .82">
              <geom fromto="0 0 0 0 0 0.1" name="head" rgba="0.8 0.6 0.4 1.0" size="0.06" type="capsule" />
              <inertial diaginertia="1.432992 1.432992 0.001" mass="43.4886" pos="0 0 0.2941" />
            </body>
          </body>
        </body>
      </body>
    </body>

  </worldbody>
  <actuator>
    <motor ctrllimited="true" ctrlrange="-0.5 1.0" gear="80" joint="ank" name="ank"/>
    <motor ctrllimited="true" ctrlrange="-1.0 1.0" gear="150" joint="hip" name="hip"/>
  </actuator>
</mujoco>